<?xml version='1.0'?>

<robot name="my_robot" xmlns:xacro="http://www.ros.org/wiki/xacro">

  <xacro:include filename="$(find racecar_eklavya)/urdf/my_robot.gazebo" />
  <link name="robot_footprint"></link>

  <joint name="robot_footprint_joint" type="fixed">
    <origin xyz="0 0 0" rpy="0 0 0" />
    <parent link="robot_footprint"/>
    <child link="chassis" />
  </joint>

  <link
    name="chassis">
    <inertial>
      <origin
        xyz="-0.0958133923403369 -2.27563018667665E-06 0.0145539997290763"
        rpy="0 0 0" />
      <mass
        value="6.78003193648517" />
      <inertia
        ixx="0.0213363092460489"
        ixy="5.40950247339377E-08"
        ixz="-0.000249956847087839"
        iyy="0.113723385248228"
        iyz="-5.58676125268779E-08"
        izz="0.128537247306062" />
    </inertial>
    <visual>
      <origin
        xyz="0 0 0"
        rpy="0 0 0" />
      <geometry>
        <mesh
          filename="package://racecar_eklavya/meshes/base_link.STL" />
      </geometry>
      <material
        name="">
        <color
          rgba="0.792156862745098 0.819607843137255 0.933333333333333 1" />
      </material>
    </visual>
    <collision>
      
      <origin
        xyz="0 0 0"
        rpy="0 0 0" />
      <geometry>
        <mesh
          filename="package://racecar_eklavya/meshes/base_link.STL" />
      </geometry>
    </collision>
  </link>



  <joint type="continuous" name="left_wheel_hinge">
    <origin
      xyz="0.12 0.2 -0.02"
      rpy="0 0 0" />
    <parent
      link="chassis" />
    <child
      link="left_wheel" />
    <axis
      xyz="0 1 0" rpy="0 0 0"/>
    
  </joint>

  <link name="left_wheel">

    <inertial>
      <origin
        xyz="-1.89376292425436E-12 -0.0310103769760117 4.59632332194815E-13"
        rpy="0 0 0" />
      <mass
        value="1.70383251159279" />
      <inertia
        ixx="0.00449158610281422"
        ixy="-1.34110727409117E-13"
        ixz="-3.31900178997306E-13"
        iyy="0.00645305207636973"
        iyz="3.57698040849964E-14"
        izz="0.0044915861026334" />
    </inertial>
    <visual>
      <origin
        xyz="0 0 0"
        rpy="0 0 0" />
      <geometry>
        <mesh
          filename="package://racecar_eklavya/meshes/FLW_Link.STL" />
      </geometry>
      <material
        name="">
        <color
          rgba="0.792156862745098 0.819607843137255 0.933333333333333 1" />
      </material>
    </visual>
    <collision>
      <surface>
        <friction>
          <ode>
            <mu>1000.0</mu>
            <mu2>1000.0</mu2>
          </ode>
        </friction>
      </surface>
      <origin
        xyz="0 0 0"
        rpy="0 0 0" />
      <geometry>
        <mesh
          filename="package://racecar_eklavya/meshes/FLW_Link.STL" />
      </geometry>
    </collision>

  </link>

  <joint type="continuous" name="right_wheel_hinge">
    <origin
      xyz="0.12 -0.2 -0.02"
      rpy="0 0 0" />
    <parent
      link="chassis" />
    <child
      link="right_wheel" />
    <axis
      xyz="0 1 0" />
    
  </joint>

  <link name="right_wheel">

    <inertial>
      <origin
        xyz="6.03600502913082E-13 0.0310103769760125 1.89792626059671E-12"
        rpy="0 0 0" />
      <mass
        value="1.70383251159284" />
      <inertia
        ixx="0.0044915861023864"
        ixy="-4.01185982983383E-14"
        ixz="-6.75380614630461E-14"
        iyy="0.00645305207637096"
        iyz="-1.32940000266363E-13"
        izz="0.00449158610306212" />
    </inertial>
    <visual>
      <origin
        xyz="0 0 0"
        rpy="0 0 0" />
      <geometry>
        <mesh
          filename="package://racecar_eklavya/meshes/FRW_Link.STL" />
      </geometry>
      <material
        name="">
        <color
          rgba="0.792156862745098 0.819607843137255 0.933333333333333 1" />
      </material>
    </visual>
    <collision>
      <surface>
        <friction>
          <ode>
            <mu>1000.0</mu>
            <mu2>1000.0</mu2>
          </ode>
        </friction>
      </surface>
      <origin
        xyz="0 0 0"
        rpy="0 0 0" />
      <geometry>
        <mesh
          filename="package://racecar_eklavya/meshes/FRW_Link.STL" />
      </geometry>
    </collision>
    
  </link>

  <link
    name="RLW_Link">
    <inertial>
      <origin
        xyz="1.75376380084913E-12 -0.368989623023988 8.50652881467795E-13"
        rpy="0 0 0" />
      <mass
        value="1.7038325115928" />
      <inertia
        ixx="0.00449158610266538"
        ixy="-1.23165748923666E-13"
        ixz="3.3894218404011E-13"
        iyy="0.00645305207636965"
        iyz="-6.39958108322924E-14"
        izz="0.00449158610278221" />
    </inertial>
    <visual>
      <origin
        xyz="0 0 0"
        rpy="0 0 0" />
      <geometry>
        <mesh
          filename="package://racecar_eklavya/meshes/RLW_Link.STL" />
      </geometry>
      <material
        name="">
        <color
          rgba="0.792156862745098 0.819607843137255 0.933333333333333 1" />
      </material>
    </visual>
    <collision>
      <surface>
        <friction>
          <ode>
            <mu>1000.0</mu>
            <mu2>1000.0</mu2>
          </ode>
        </friction>
      </surface>
      <origin
        xyz="0 0 0"
        rpy="0 0 0" />
      <geometry>
        <mesh
          filename="package://racecar_eklavya/meshes/RLW_Link.STL" />
      </geometry>
    </collision>
  </link>
  <joint
    name="RLW_Joints"
    type="continuous">
    <origin
      xyz="-0.12 0.2 -0.0199999999999997"
      rpy="0 0 0" />
    <parent
      link="chassis" />
    <child
      link="RLW_Link" />
    <axis
      xyz="0 -1 0" />
  </joint>
  <link
    name="RRW_Link">
    <inertial>
      <origin
        xyz="1.75376380084913E-12 0.031010376976012 8.50708392619026E-13"
        rpy="0 0 0" />
      <mass
        value="1.7038325115928" />
      <inertia
        ixx="0.00449158610266538"
        ixy="-1.2316574883802E-13"
        ixz="3.38942213669035E-13"
        iyy="0.00645305207636965"
        iyz="-6.39958105848474E-14"
        izz="0.00449158610278221" />
    </inertial>
    <visual>
      <origin
        xyz="0 0 0"
        rpy="0 0 0" />
      <geometry>
        <mesh
          filename="package://racecar_eklavya/meshes/RRW_Link.STL" />
      </geometry>
      <material
        name="">
        <color
          rgba="0.792156862745098 0.819607843137255 0.933333333333333 1" />
      </material>
    </visual>
    <collision>
      <surface>
        <friction>
          <ode>
            <mu>1000.0</mu>
            <mu2>1000.0</mu2>
          </ode>
        </friction>
      </surface>
      <origin
        xyz="0 0 0"
        rpy="0 0 0" />
      <geometry>
        <mesh
          filename="package://racecar_eklavya/meshes/RRW_Link.STL" />
      </geometry>
    </collision>
  </link>
  <joint
    name="RRW_Joints"
    type="continuous">
    <origin
      xyz="-0.12 -0.2 -0.0199999999999998"
      rpy="0 0 0" />
    <parent
      link="chassis" />
    <child
      link="RRW_Link" />
    <axis
      xyz="0 -1 0" />
  </joint>


  <joint type="fixed" name="camera_joint">
    <origin xyz="0.19 0 0.1" rpy="0 0 0"/>
    <child link="camera"/>
    <parent link="chassis"/>
    <axis xyz="0 1 0" rpy="0 0 0"/>
  </joint>

  <link name="camera">

    <inertial>
      <mass value="0.1"/>
      <origin xyz="0.0 0 0" rpy="0 0 0"/>
      <inertia
          ixx="1e-6" ixy="0" ixz="0"
          iyy="1e-6" iyz="0"
          izz="1e-6"
      />
      <box_inertia m="0.1" x="0.05" y="0.05" z="0.05"/>
    </inertial>

    <visual>
      <origin xyz="0 0 0" rpy="0 0 0"/>
      <geometry>
        <box size="0.05 0.05 0.05"/>
      </geometry>
    </visual>

    <collision>
      <origin xyz="0 0 0" rpy="0 0 0"/>
      <geometry>
        <box size="0.05 0.05 0.05"/>
      </geometry>
    </collision>
    
  </link>

  <joint type="fixed" name="hokuyo_joint_1">
    <origin xyz="0.12 -0.07 0.12" rpy="0 0 0"/>
    <child link="hokuyo_1"/>
    <parent link="chassis"/>
    <axis xyz="0 1 0" rpy="0 0 0"/>
  </joint>

  <link name="hokuyo_1">

    <inertial>
      <mass value="1e-5"/>
      <origin xyz="0.0 0 0" rpy="0 0 0"/>
      <inertia
          ixx="1e-6" ixy="0" ixz="0"
          iyy="1e-6" iyz="0"
          izz="1e-6"
      />
    </inertial>

    <visual>
      <origin xyz="0 0 0" rpy="0 0 0"/>
      <geometry>
        <mesh filename="package://racecar_eklavya/meshes/hokuyo.dae"/>
      </geometry>
    </visual>

    <collision>
      <origin xyz="0 0 0" rpy="0 0 0"/>
      <geometry>
        <box size="0.1 0.1 0.1"/>
      </geometry>
    </collision>
    
  </link>

  <joint type="fixed" name="hokuyo_joint_2">
    <origin xyz="0.12 0.07 0.12" rpy="0 0 0"/>
    <child link="hokuyo_2"/>
    <parent link="chassis"/>
    <axis xyz="0 1 0" rpy="0 0 0"/>
  </joint>

  <link name="hokuyo_2">

    <inertial>
      <mass value="1e-5"/>
      <origin xyz="0.0 0 0" rpy="0 0 0"/>
      <inertia
          ixx="1e-6" ixy="0" ixz="0"
          iyy="1e-6" iyz="0"
          izz="1e-6"
      />
    </inertial>

    <visual>
      <origin xyz="0 0 0" rpy="0 0 0"/>
      <geometry>
        <mesh filename="package://racecar_eklavya/meshes/hokuyo.dae"/>
      </geometry>
    </visual>

    <collision>
      <origin xyz="0 0 0" rpy="0 0 0"/>
      <geometry>
        <box size="0.1 0.1 0.1"/>
      </geometry>
    </collision>
    
  </link>


  <!-- IMU SENSOR -->
  <joint type="fixed" name="imu_joint">
    <origin xyz="0.12 0 0.12" rpy="0 0 0"/>
    <child link="imu_link"/>
    <parent link="chassis"/>
    <axis xyz="0 1 0" rpy="0 0 0"/>
  </joint>
  <link name="imu_link">

    <inertial>
      <mass value="1e-5"/>
      <origin xyz="0.0 0 0" rpy="0 0 0"/>
      <inertia
          ixx="1e-6" ixy="0" ixz="0"
          iyy="1e-6" iyz="0"
          izz="1e-6"
      />
    </inertial>

    <visual>
      <origin xyz="0 0 0" rpy="0 0 0"/>
      <geometry>
        <box size="0.05 0.05 0.05"/>
      </geometry>
    </visual>

    <collision>
      <origin xyz="0 0 0" rpy="0 0 0"/>
      <geometry>
        <box size="0.1 0.1 0.1"/>
      </geometry>
    </collision>
    
  </link>




  <gazebo reference="chassis">
    <material>Gazebo/Red</material>
  </gazebo>

  <gazebo reference="left_wheel">
    
    <material>Gazebo/DarkGrey</material>
  </gazebo>

  <gazebo reference="right_wheel">
    
    <material>Gazebo/DarkGrey</material>
  </gazebo>

  <gazebo reference="RRW_Link">
   
    <material>Gazebo/DarkGrey</material>
  </gazebo>

  <gazebo reference="RLW_Link">
    
    <material>Gazebo/DarkGrey</material>
  </gazebo>

  <gazebo reference="camera">
    <material>Gazebo/Blue</material>
  </gazebo>
  <gazebo reference="imu_link">
    <material>Gazebo/Yellow</material>
  </gazebo>


</robot>
