<?xml version="1.0"?>
<!-- This URDF was automatically created by SolidWorks to URDF Exporter! Originally created by Stephen Brawner (brawner@gmail.com) 
     Commit Version: 1.6.0-4-g7f85cfe  Build Version: 1.6.7995.38578
     For more information, please see http://wiki.ros.org/sw_urdf_exporter -->
<robot
  name="racecar_updated_urdf" xmlns:xacro="http://www.ros.org/wiki/xacro">

  



  <link name="robot_footprint"></link>

  <joint name="robot_footprint_joint" type="fixed">
    <origin xyz="0 0 0" rpy="0 0 0" />
    <parent link="robot_footprint"/>
    <child link="chassis" />
  </joint>

  <link name='chassis'>
    <pose>0 0 0.3 0 0 0</pose>

    <inertial>
      <origin
        xyz="-0.00874380820178244 1.9755530544785E-10 0.0195865275005581"
        rpy="0 0 0" />
      
      <mass
        value="10.1700980282457" />
      <inertia
        ixx="0.0349630785341739"
        ixy="-2.97162798603271E-13"
        ixz="0.0015480542890569"
        iyy="0.12849266986443"
        iyz="-1.32691523977453E-10"
        izz="0.152583047232211" />
    </inertial>
    <visual>
      <origin
        xyz="0 0 0"
        rpy="0 0 0" />
      <geometry>
        <mesh
          filename="package://racecar_updated_urdf/meshes/base_link.STL" />
      </geometry>
      <!-- <material
        name="">
        <color
          rgba="0.792156862745098 0.819607843137255 0.933333333333333 1" />
      </material> -->
      
    </visual>
    <collision>
      <origin
        xyz="0 0 0"
        rpy="0 0 0" />
      <geometry>
        <mesh
          filename="package://racecar_updated_urdf/meshes/base_link.STL" />
      </geometry>
    </collision>

  </link>


  <joint type="continuous" name="left_wheel_hinge">
    <origin xyz="0.24 0.205 -0.02" rpy="0 0 0" />
    <parent link="chassis" />
    <child link="left_wheel" />
    <axis xyz="0 1 0" />
    <limit effort="10000" velocity="1000"/>
    <dynamics damping="1.0" friction="1.0"/>
  </joint>

  <link name="left_wheel">

    <inertial>
      <origin
        xyz="-7.35089072945172E-13 -0.0360103769760128 -1.84885440290827E-12"
        rpy="0 0 0" />
      <mass
        value="1.70383251159284" />
      <inertia
        ixx="0.00449158610273131"
        ixy="-5.46441835565891E-14"
        ixz="3.44311152786284E-13"
        iyy="0.00645305207637073"
        iyz="-1.27658872884525E-13"
        izz="0.0044915861027171" />
    </inertial>
    <visual>
      <origin
        xyz="0 0 0"
        rpy="0 0 0" />
      <geometry>
        <mesh
          filename="package://racecar_updated_urdf/meshes/FLW_Link.STL" />
      </geometry>
      <material
        name="">
        <color
          rgba="0.298039215686275 0.298039215686275 0.298039215686275 1" />
      </material>
    </visual>
    <collision>
      <origin
        xyz="0 0 0"
        rpy="0 0 0" />
      <geometry>
        <mesh
          filename="package://racecar_updated_urdf/meshes/FLW_Link.STL" />
      </geometry>
    </collision>

  </link>

  <joint type="continuous" name="right_wheel_hinge">
    <origin
      xyz="0.24 0.205 -0.02"
      rpy="0 0 0" />
    <parent
      link="chassis" />
    <child
      link="right_wheel" />
    <axis
      xyz="0 1 0" />
    <limit effort="10000" velocity="1000"/>
    <dynamics damping="1.0" friction="1.0"/>
  </joint>

  <link name="right_wheel">

    <inertial>
      <origin
        xyz="6.03593564019178E-13 0.0360103769760126 1.89792626059671E-12"
        rpy="0 0 0" />
      <mass
        value="1.70383251159284" />
      <inertia
        ixx="0.00449158610238641"
        ixy="-4.01189217425287E-14"
        ixz="-6.75412384155045E-14"
        iyy="0.00645305207637097"
        iyz="-1.32942219598239E-13"
        izz="0.00449158610306213" />
    </inertial>
    <visual>
      <origin
        xyz="0 0 0"
        rpy="0 0 0" />
      <geometry>
        <mesh
          filename="package://racecar_updated_urdf/meshes/FRW_Link.STL" />
      </geometry>
      <material
        name="">
        <color
          rgba="0.298039215686275 0.298039215686275 0.298039215686275 1" />
      </material>
    </visual>
    <collision>
      <origin
        xyz="0 0 0"
        rpy="0 0 0" />
      <geometry>
        <mesh
          filename="package://racecar_updated_urdf/meshes/FRW_Link.STL" />
      </geometry>
    </collision>
    
  </link>


  <joint type="fixed" name="camera_joint">
    <origin xyz="0.19 0 0" rpy="0 0 0"/>
    <child link="camera"/>
    <parent link="chassis"/>
    <axis xyz="0 1 0" rpy="0 0 0"/>
  </joint>

  <link name="camera">

    <inertial>
      <mass value="0.1"/>
      <origin xyz="0.0 0 0" rpy="0 0 0"/>
      <inertia
          ixx="1e-6" ixy="0" ixz="0"
          iyy="1e-6" iyz="0"
          izz="1e-6"
      />
      <box_inertia m="0.1" x="0.05" y="0.05" z="0.05"/>
    </inertial>
    <visual>
      <origin xyz="0 0 0" rpy="0 0 0"/>
      <geometry>
        <box size="0.05 0.05 0.05"/>
      </geometry>
    </visual>

    <collision>
      <origin xyz="0 0 0" rpy="0 0 0"/>
      <geometry>
        <box size="0.05 0.05 0.05"/>
      </geometry>
    </collision>
    
  </link>

  <joint type="fixed" name="hokuyo_joint">
    <origin xyz="0.15 0 0.07" rpy="0 0 0"/>
    <child link="hokuyo"/>
    <parent link="chassis"/>
    <axis xyz="0 1 0" rpy="0 0 0"/>
  </joint>

  <link name="hokuyo">

    <inertial>
      <mass value="1e-5"/>
      <origin xyz="0.0 0 0" rpy="0 0 0"/>
      <inertia
          ixx="1e-6" ixy="0" ixz="0"
          iyy="1e-6" iyz="0"
          izz="1e-6"
      />
    </inertial>

    <visual>
      <origin xyz="0 0 0" rpy="0 0 0"/>
      <geometry>
        <mesh filename="package://racecar_updated_urdf/meshes/hokuyo.dae"/>
      </geometry>
    </visual>

    <collision>
      <origin xyz="0 0 0" rpy="0 0 0"/>
      <geometry>
        <box size="0.1 0.1 0.1"/>
      </geometry>
    </collision>
    
  </link>

  <gazebo reference="chassis">
    <material>Gazebo/Turquoise</material>
  </gazebo>

  <gazebo reference="left_wheel">
    <material>Gazebo/DarkGrey</material>
  </gazebo>

  <gazebo reference="right_wheel">
    <material>Gazebo/DarkGrey</material>
  </gazebo>

  <gazebo reference="camera">
    <material>Gazebo/RedBright</material>
  </gazebo>
     
	
	
  <gazebo>
    <plugin name="differential_drive_controller" filename="libgazebo_ros_diff_drive.so">
      <legacyMode>false</legacyMode>
      <alwaysOn>true</alwaysOn>
      <updateRate>10</updateRate>
      <leftJoint>left_wheel_hinge</leftJoint>
      <rightJoint>right_wheel_hinge</rightJoint>
      <wheelSeparation>0.23</wheelSeparation>
      <wheelDiameter>0.16</wheelDiameter>
      <torque>10</torque>
      <commandTopic>cmd_vel</commandTopic>
      <odometryTopic>odom</odometryTopic>
      <odometryFrame>odom</odometryFrame>
      <robotBaseFrame>robot_footprint</robotBaseFrame>
      <publishWheelTF>false</publishWheelTF>
      <publishWheelJointState>false</publishWheelJointState>
      <rosDebugLevel>na</rosDebugLevel>
      <wheelAcceleration>0</wheelAcceleration>
      <wheelTorque>5</wheelTorque>
      <odometrySource>world</odometrySource>
      <publishTf>1</publishTf>
      <publishOdomTF>true</publishOdomTF>
    </plugin>
  </gazebo>

  <!-- camera -->
  <gazebo reference="camera">
    <sensor type="camera" name="camera1">
      <update_rate>30.0</update_rate>
      <camera name="head">
        <horizontal_fov>1.3962634</horizontal_fov>
        <image>
          <width>800</width>
          <height>800</height>
          <format>R8G8B8</format>
        </image>
        <clip>
          <near>0.02</near>
          <far>300</far>
        </clip>
      </camera>
      <plugin name="camera_controller" filename="libgazebo_ros_camera.so">
        <alwaysOn>true</alwaysOn>
        <updateRate>0.0</updateRate>
        <cameraName>camera</cameraName>
        <imageTopicName>rgb/image_raw</imageTopicName>
        <cameraInfoTopicName>rgb/camera_info</cameraInfoTopicName>
        <frameName>camera</frameName>
        <hackBaseline>0.07</hackBaseline>
        <distortionK1>0.0</distortionK1>
        <distortionK2>0.0</distortionK2>
        <distortionK3>0.0</distortionK3>
        <distortionT1>0.0</distortionT1>
        <distortionT2>0.0</distortionT2>
      </plugin>
    </sensor>
  </gazebo>

  <!-- hokuyo -->
  <gazebo reference="hokuyo">
    <sensor type="ray" name="head_hokuyo_sensor">
      <pose>0 0 0 0 0 0</pose>
      <visualize>false</visualize>
      <update_rate>40</update_rate>
      <ray>
        <scan>
          <horizontal>
            <samples>720</samples>
            <resolution>1</resolution>
            <min_angle>-1.570796</min_angle>
            <max_angle>1.570796</max_angle>
          </horizontal>
        </scan>
        <range>
          <min>0.10</min>
          <max>30.0</max>
          <resolution>0.01</resolution>
        </range>
        <noise>
          <type>gaussian</type>
          <!-- Noise parameters based on published spec for Hokuyo laser
               achieving "+-30mm" accuracy at range < 10m.  A mean of 0.0m and
               stddev of 0.01m will put 99.7% of samples within 0.03m of the true
               reading. -->
          <mean>0.0</mean>
          <stddev>0.01</stddev>
        </noise>
      </ray>
      <plugin name="gazebo_ros_head_hokuyo_controller" filename="libgazebo_ros_laser.so">
        <topicName>/scan</topicName>
        <frameName>hokuyo</frameName>
      </plugin>
    </sensor>
  </gazebo>
	
  
  
  
  
  
  
  
</robot>
